[2024-02-17T17:58:56.661-0300] {logging_mixin.py:151} INFO - Changing /mnt/c/Users/filipe.macedo_ifood/Documents/how-desafio-03/airflow/logs/dag_id=how-desafio-3/run_id=manual__2024-02-17T20:58:42.162040+00:00/task_id=wait_for_step permission to 509
[2024-02-17T17:58:56.721-0300] {logging_mixin.py:151} INFO - Changing /mnt/c/Users/filipe.macedo_ifood/Documents/how-desafio-03/airflow/logs/dag_id=how-desafio-3/run_id=manual__2024-02-17T20:58:42.162040+00:00/task_id=wait_for_step permission to 509
[2024-02-17T17:58:56.745-0300] {taskinstance.py:1159} INFO - Dependencies all met for dep_context=non-requeueable deps ti=<TaskInstance: how-desafio-3.wait_for_step manual__2024-02-17T20:58:42.162040+00:00 [queued]>
[2024-02-17T17:58:56.761-0300] {taskinstance.py:1159} INFO - Dependencies all met for dep_context=requeueable deps ti=<TaskInstance: how-desafio-3.wait_for_step manual__2024-02-17T20:58:42.162040+00:00 [queued]>
[2024-02-17T17:58:56.761-0300] {taskinstance.py:1361} INFO - Starting attempt 1 of 1
[2024-02-17T17:58:56.794-0300] {taskinstance.py:1382} INFO - Executing <Task(EmrStepSensor): wait_for_step> on 2024-02-17 20:58:42.162040+00:00
[2024-02-17T17:58:56.796-0300] {standard_task_runner.py:57} INFO - Started process 3098 to run task
[2024-02-17T17:58:56.798-0300] {standard_task_runner.py:84} INFO - Running: ['airflow', 'tasks', 'run', 'how-desafio-3', 'wait_for_step', 'manual__2024-02-17T20:58:42.162040+00:00', '--job-id', '355', '--raw', '--subdir', 'DAGS_FOLDER/weather_dag.py', '--cfg-path', '/tmp/tmpk9oa1gu1']
[2024-02-17T17:58:56.800-0300] {standard_task_runner.py:85} INFO - Job 355: Subtask wait_for_step
[2024-02-17T17:58:56.859-0300] {logging_mixin.py:151} INFO - Changing /mnt/c/Users/filipe.macedo_ifood/Documents/how-desafio-03/airflow/logs/dag_id=how-desafio-3/run_id=manual__2024-02-17T20:58:42.162040+00:00/task_id=wait_for_step permission to 509
[2024-02-17T17:58:56.860-0300] {task_command.py:416} INFO - Running <TaskInstance: how-desafio-3.wait_for_step manual__2024-02-17T20:58:42.162040+00:00 [running]> on host 14111-NB.
[2024-02-17T17:58:56.968-0300] {taskinstance.py:1662} INFO - Exporting env vars: AIRFLOW_CTX_DAG_OWNER='airflow' AIRFLOW_CTX_DAG_ID='how-desafio-3' AIRFLOW_CTX_TASK_ID='wait_for_step' AIRFLOW_CTX_EXECUTION_DATE='2024-02-17T20:58:42.162040+00:00' AIRFLOW_CTX_TRY_NUMBER='1' AIRFLOW_CTX_DAG_RUN_ID='manual__2024-02-17T20:58:42.162040+00:00'
[2024-02-17T17:58:56.977-0300] {base.py:73} INFO - Using connection ID 'aws_default' for task execution.
[2024-02-17T17:58:56.978-0300] {connection_wrapper.py:340} INFO - AWS Connection (conn_id='aws_default', conn_type='aws') credentials retrieved from login and password.
[2024-02-17T17:58:57.187-0300] {emr.py:575} INFO - Poking step s-00372091MDZB2M0BGKSE on cluster j-15NLJT9J3VV3V
[2024-02-17T17:58:58.356-0300] {emr.py:79} INFO - Job flow currently PENDING
[2024-02-17T17:59:58.366-0300] {emr.py:575} INFO - Poking step s-00372091MDZB2M0BGKSE on cluster j-15NLJT9J3VV3V
[2024-02-17T17:59:59.442-0300] {emr.py:79} INFO - Job flow currently PENDING
[2024-02-17T18:00:59.496-0300] {emr.py:575} INFO - Poking step s-00372091MDZB2M0BGKSE on cluster j-15NLJT9J3VV3V
[2024-02-17T18:01:00.740-0300] {emr.py:79} INFO - Job flow currently CANCELLED
[2024-02-17T18:01:00.747-0300] {taskinstance.py:1937} ERROR - Task failed with exception
Traceback (most recent call last):
  File "/usr/local/lib/python3.10/dist-packages/airflow/providers/amazon/aws/sensors/emr.py", line 624, in execute
    super().execute(context=context)
  File "/usr/local/lib/python3.10/dist-packages/airflow/sensors/base.py", line 257, in execute
    raise e
  File "/usr/local/lib/python3.10/dist-packages/airflow/sensors/base.py", line 239, in execute
    poke_return = self.poke(context)
  File "/usr/local/lib/python3.10/dist-packages/airflow/providers/amazon/aws/sensors/emr.py", line 85, in poke
    raise AirflowException(f"EMR job failed: {self.failure_message_from_response(response)}")
airflow.exceptions.AirflowException: EMR job failed: None
[2024-02-17T18:01:00.751-0300] {taskinstance.py:1400} INFO - Marking task as FAILED. dag_id=how-desafio-3, task_id=wait_for_step, execution_date=20240217T205842, start_date=20240217T205856, end_date=20240217T210100
[2024-02-17T18:01:00.786-0300] {standard_task_runner.py:104} ERROR - Failed to execute job 355 for task wait_for_step (EMR job failed: None; 3098)
[2024-02-17T18:01:00.820-0300] {local_task_job_runner.py:228} INFO - Task exited with return code 1
[2024-02-17T18:01:00.850-0300] {taskinstance.py:2778} INFO - 0 downstream tasks scheduled from follow-on schedule check
