[2024-01-26T14:35:49.878-0300] {logging_mixin.py:151} INFO - Changing /mnt/c/Users/filipe.macedo_ifood/Documents/how-desafio-03/airflow/logs/dag_id=how-desafio-03/run_id=scheduled__2024-01-26T17:15:00+00:00/task_id=invoke_lambda_function permission to 509
[2024-01-26T14:35:49.936-0300] {logging_mixin.py:151} INFO - Changing /mnt/c/Users/filipe.macedo_ifood/Documents/how-desafio-03/airflow/logs/dag_id=how-desafio-03/run_id=scheduled__2024-01-26T17:15:00+00:00/task_id=invoke_lambda_function permission to 509
[2024-01-26T14:35:49.955-0300] {taskinstance.py:1159} INFO - Dependencies all met for dep_context=non-requeueable deps ti=<TaskInstance: how-desafio-03.invoke_lambda_function scheduled__2024-01-26T17:15:00+00:00 [queued]>
[2024-01-26T14:35:49.966-0300] {taskinstance.py:1159} INFO - Dependencies all met for dep_context=requeueable deps ti=<TaskInstance: how-desafio-03.invoke_lambda_function scheduled__2024-01-26T17:15:00+00:00 [queued]>
[2024-01-26T14:35:49.966-0300] {taskinstance.py:1361} INFO - Starting attempt 2 of 2
[2024-01-26T14:35:49.995-0300] {taskinstance.py:1382} INFO - Executing <Task(LambdaInvokeFunctionOperator): invoke_lambda_function> on 2024-01-26 17:15:00+00:00
[2024-01-26T14:35:49.997-0300] {standard_task_runner.py:57} INFO - Started process 3776 to run task
[2024-01-26T14:35:49.999-0300] {standard_task_runner.py:84} INFO - Running: ['airflow', 'tasks', 'run', 'how-desafio-03', 'invoke_lambda_function', 'scheduled__2024-01-26T17:15:00+00:00', '--job-id', '230', '--raw', '--subdir', 'DAGS_FOLDER/weather_dag.py', '--cfg-path', '/tmp/tmpxjqn6tvw']
[2024-01-26T14:35:50.000-0300] {standard_task_runner.py:85} INFO - Job 230: Subtask invoke_lambda_function
[2024-01-26T14:35:50.067-0300] {logging_mixin.py:151} INFO - Changing /mnt/c/Users/filipe.macedo_ifood/Documents/how-desafio-03/airflow/logs/dag_id=how-desafio-03/run_id=scheduled__2024-01-26T17:15:00+00:00/task_id=invoke_lambda_function permission to 509
[2024-01-26T14:35:50.069-0300] {task_command.py:416} INFO - Running <TaskInstance: how-desafio-03.invoke_lambda_function scheduled__2024-01-26T17:15:00+00:00 [running]> on host 14111-NB.
[2024-01-26T14:35:50.155-0300] {taskinstance.py:1662} INFO - Exporting env vars: AIRFLOW_CTX_DAG_OWNER='airflow' AIRFLOW_CTX_DAG_ID='how-desafio-03' AIRFLOW_CTX_TASK_ID='invoke_lambda_function' AIRFLOW_CTX_EXECUTION_DATE='2024-01-26T17:15:00+00:00' AIRFLOW_CTX_TRY_NUMBER='2' AIRFLOW_CTX_DAG_RUN_ID='scheduled__2024-01-26T17:15:00+00:00'
[2024-01-26T14:35:50.156-0300] {lambda_function.py:211} INFO - Invoking AWS Lambda function: how-desafio-03 with payload: {"date": "1706290200"}
[2024-01-26T14:35:50.166-0300] {base.py:73} INFO - Using connection ID 'aws_default' for task execution.
[2024-01-26T14:35:50.167-0300] {connection_wrapper.py:340} INFO - AWS Connection (conn_id='aws_default', conn_type='aws') credentials retrieved from login and password.
[2024-01-26T14:35:51.341-0300] {taskinstance.py:1937} ERROR - Task failed with exception
Traceback (most recent call last):
  File "/usr/local/lib/python3.10/dist-packages/airflow/providers/amazon/aws/operators/lambda_function.py", line 212, in execute
    response = self.hook.invoke_lambda(
  File "/usr/local/lib/python3.10/dist-packages/airflow/providers/amazon/aws/hooks/lambda_function.py", line 79, in invoke_lambda
    return self.conn.invoke(**trim_none_values(invoke_args))
  File "/home/fcmacedo/.local/lib/python3.10/site-packages/botocore/client.py", line 535, in _api_call
    return self._make_api_call(operation_name, kwargs)
  File "/home/fcmacedo/.local/lib/python3.10/site-packages/botocore/client.py", line 980, in _make_api_call
    raise error_class(parsed_response, operation_name)
botocore.exceptions.ClientError: An error occurred (InvalidSignatureException) when calling the Invoke operation: Signature expired: 20240126T173550Z is now earlier than 20240126T175007Z (20240126T175507Z - 5 min.)
[2024-01-26T14:35:51.355-0300] {taskinstance.py:1400} INFO - Marking task as FAILED. dag_id=how-desafio-03, task_id=invoke_lambda_function, execution_date=20240126T171500, start_date=20240126T173549, end_date=20240126T173551
[2024-01-26T14:35:51.389-0300] {standard_task_runner.py:104} ERROR - Failed to execute job 230 for task invoke_lambda_function (An error occurred (InvalidSignatureException) when calling the Invoke operation: Signature expired: 20240126T173550Z is now earlier than 20240126T175007Z (20240126T175507Z - 5 min.); 3776)
[2024-01-26T14:35:51.437-0300] {local_task_job_runner.py:228} INFO - Task exited with return code 1
[2024-01-26T14:35:51.462-0300] {taskinstance.py:2778} INFO - 0 downstream tasks scheduled from follow-on schedule check
[2024-01-26T14:39:55.218-0300] {logging_mixin.py:151} INFO - Changing /mnt/c/Users/filipe.macedo_ifood/Documents/how-desafio-03/airflow/logs/dag_id=how-desafio-03/run_id=scheduled__2024-01-26T17:15:00+00:00/task_id=invoke_lambda_function permission to 509
[2024-01-26T14:39:55.274-0300] {logging_mixin.py:151} INFO - Changing /mnt/c/Users/filipe.macedo_ifood/Documents/how-desafio-03/airflow/logs/dag_id=how-desafio-03/run_id=scheduled__2024-01-26T17:15:00+00:00/task_id=invoke_lambda_function permission to 509
[2024-01-26T14:39:55.292-0300] {taskinstance.py:1159} INFO - Dependencies all met for dep_context=non-requeueable deps ti=<TaskInstance: how-desafio-03.invoke_lambda_function scheduled__2024-01-26T17:15:00+00:00 [queued]>
[2024-01-26T14:39:55.304-0300] {taskinstance.py:1159} INFO - Dependencies all met for dep_context=requeueable deps ti=<TaskInstance: how-desafio-03.invoke_lambda_function scheduled__2024-01-26T17:15:00+00:00 [queued]>
[2024-01-26T14:39:55.304-0300] {taskinstance.py:1361} INFO - Starting attempt 2 of 2
[2024-01-26T14:39:55.337-0300] {taskinstance.py:1382} INFO - Executing <Task(LambdaInvokeFunctionOperator): invoke_lambda_function> on 2024-01-26 17:15:00+00:00
[2024-01-26T14:39:55.339-0300] {standard_task_runner.py:57} INFO - Started process 3886 to run task
[2024-01-26T14:39:55.342-0300] {standard_task_runner.py:84} INFO - Running: ['airflow', 'tasks', 'run', 'how-desafio-03', 'invoke_lambda_function', 'scheduled__2024-01-26T17:15:00+00:00', '--job-id', '234', '--raw', '--subdir', 'DAGS_FOLDER/weather_dag.py', '--cfg-path', '/tmp/tmpj73m_0ba']
[2024-01-26T14:39:55.343-0300] {standard_task_runner.py:85} INFO - Job 234: Subtask invoke_lambda_function
[2024-01-26T14:39:55.413-0300] {logging_mixin.py:151} INFO - Changing /mnt/c/Users/filipe.macedo_ifood/Documents/how-desafio-03/airflow/logs/dag_id=how-desafio-03/run_id=scheduled__2024-01-26T17:15:00+00:00/task_id=invoke_lambda_function permission to 509
[2024-01-26T14:39:55.415-0300] {task_command.py:416} INFO - Running <TaskInstance: how-desafio-03.invoke_lambda_function scheduled__2024-01-26T17:15:00+00:00 [running]> on host 14111-NB.
[2024-01-26T14:39:55.504-0300] {taskinstance.py:1662} INFO - Exporting env vars: AIRFLOW_CTX_DAG_OWNER='airflow' AIRFLOW_CTX_DAG_ID='how-desafio-03' AIRFLOW_CTX_TASK_ID='invoke_lambda_function' AIRFLOW_CTX_EXECUTION_DATE='2024-01-26T17:15:00+00:00' AIRFLOW_CTX_TRY_NUMBER='2' AIRFLOW_CTX_DAG_RUN_ID='scheduled__2024-01-26T17:15:00+00:00'
[2024-01-26T14:39:55.505-0300] {lambda_function.py:211} INFO - Invoking AWS Lambda function: how-desafio-03 with payload: {"date": "1706290200"}
[2024-01-26T14:39:55.521-0300] {base.py:73} INFO - Using connection ID 'aws_default' for task execution.
[2024-01-26T14:39:55.521-0300] {connection_wrapper.py:340} INFO - AWS Connection (conn_id='aws_default', conn_type='aws') credentials retrieved from login and password.
[2024-01-26T14:39:56.748-0300] {taskinstance.py:1937} ERROR - Task failed with exception
Traceback (most recent call last):
  File "/usr/local/lib/python3.10/dist-packages/airflow/providers/amazon/aws/operators/lambda_function.py", line 212, in execute
    response = self.hook.invoke_lambda(
  File "/usr/local/lib/python3.10/dist-packages/airflow/providers/amazon/aws/hooks/lambda_function.py", line 79, in invoke_lambda
    return self.conn.invoke(**trim_none_values(invoke_args))
  File "/home/fcmacedo/.local/lib/python3.10/site-packages/botocore/client.py", line 535, in _api_call
    return self._make_api_call(operation_name, kwargs)
  File "/home/fcmacedo/.local/lib/python3.10/site-packages/botocore/client.py", line 980, in _make_api_call
    raise error_class(parsed_response, operation_name)
botocore.exceptions.ClientError: An error occurred (InvalidSignatureException) when calling the Invoke operation: Signature expired: 20240126T173955Z is now earlier than 20240126T175353Z (20240126T175853Z - 5 min.)
[2024-01-26T14:39:56.767-0300] {taskinstance.py:1400} INFO - Marking task as FAILED. dag_id=how-desafio-03, task_id=invoke_lambda_function, execution_date=20240126T171500, start_date=20240126T173955, end_date=20240126T173956
[2024-01-26T14:39:56.799-0300] {standard_task_runner.py:104} ERROR - Failed to execute job 234 for task invoke_lambda_function (An error occurred (InvalidSignatureException) when calling the Invoke operation: Signature expired: 20240126T173955Z is now earlier than 20240126T175353Z (20240126T175853Z - 5 min.); 3886)
[2024-01-26T14:39:56.831-0300] {local_task_job_runner.py:228} INFO - Task exited with return code 1
[2024-01-26T14:39:56.867-0300] {taskinstance.py:2778} INFO - 0 downstream tasks scheduled from follow-on schedule check
