[2024-01-26T14:34:19.032-0300] {logging_mixin.py:151} INFO - Changing /mnt/c/Users/filipe.macedo_ifood/Documents/how-desafio-03/airflow/logs/dag_id=how-desafio-03/run_id=manual__2024-01-26T17:34:15.310348+00:00/task_id=invoke_lambda_function permission to 509
[2024-01-26T14:34:19.096-0300] {logging_mixin.py:151} INFO - Changing /mnt/c/Users/filipe.macedo_ifood/Documents/how-desafio-03/airflow/logs/dag_id=how-desafio-03/run_id=manual__2024-01-26T17:34:15.310348+00:00/task_id=invoke_lambda_function permission to 509
[2024-01-26T14:34:19.127-0300] {taskinstance.py:1159} INFO - Dependencies all met for dep_context=non-requeueable deps ti=<TaskInstance: how-desafio-03.invoke_lambda_function manual__2024-01-26T17:34:15.310348+00:00 [queued]>
[2024-01-26T14:34:19.140-0300] {taskinstance.py:1159} INFO - Dependencies all met for dep_context=requeueable deps ti=<TaskInstance: how-desafio-03.invoke_lambda_function manual__2024-01-26T17:34:15.310348+00:00 [queued]>
[2024-01-26T14:34:19.140-0300] {taskinstance.py:1361} INFO - Starting attempt 1 of 1
[2024-01-26T14:34:19.171-0300] {taskinstance.py:1382} INFO - Executing <Task(LambdaInvokeFunctionOperator): invoke_lambda_function> on 2024-01-26 17:34:15.310348+00:00
[2024-01-26T14:34:19.173-0300] {standard_task_runner.py:57} INFO - Started process 3771 to run task
[2024-01-26T14:34:19.176-0300] {standard_task_runner.py:84} INFO - Running: ['airflow', 'tasks', 'run', 'how-desafio-03', 'invoke_lambda_function', 'manual__2024-01-26T17:34:15.310348+00:00', '--job-id', '229', '--raw', '--subdir', 'DAGS_FOLDER/weather_dag.py', '--cfg-path', '/tmp/tmp3rwc58ff']
[2024-01-26T14:34:19.177-0300] {standard_task_runner.py:85} INFO - Job 229: Subtask invoke_lambda_function
[2024-01-26T14:34:19.238-0300] {logging_mixin.py:151} INFO - Changing /mnt/c/Users/filipe.macedo_ifood/Documents/how-desafio-03/airflow/logs/dag_id=how-desafio-03/run_id=manual__2024-01-26T17:34:15.310348+00:00/task_id=invoke_lambda_function permission to 509
[2024-01-26T14:34:19.240-0300] {task_command.py:416} INFO - Running <TaskInstance: how-desafio-03.invoke_lambda_function manual__2024-01-26T17:34:15.310348+00:00 [running]> on host 14111-NB.
[2024-01-26T14:34:19.347-0300] {taskinstance.py:1662} INFO - Exporting env vars: AIRFLOW_CTX_DAG_OWNER='airflow' AIRFLOW_CTX_DAG_ID='how-desafio-03' AIRFLOW_CTX_TASK_ID='invoke_lambda_function' AIRFLOW_CTX_EXECUTION_DATE='2024-01-26T17:34:15.310348+00:00' AIRFLOW_CTX_TRY_NUMBER='1' AIRFLOW_CTX_DAG_RUN_ID='manual__2024-01-26T17:34:15.310348+00:00'
[2024-01-26T14:34:19.348-0300] {lambda_function.py:211} INFO - Invoking AWS Lambda function: how-desafio-03 with payload: {"date": "1706290200"}
[2024-01-26T14:34:19.358-0300] {base.py:73} INFO - Using connection ID 'aws_default' for task execution.
[2024-01-26T14:34:19.359-0300] {connection_wrapper.py:340} INFO - AWS Connection (conn_id='aws_default', conn_type='aws') credentials retrieved from login and password.
[2024-01-26T14:34:20.472-0300] {taskinstance.py:1937} ERROR - Task failed with exception
Traceback (most recent call last):
  File "/usr/local/lib/python3.10/dist-packages/airflow/providers/amazon/aws/operators/lambda_function.py", line 212, in execute
    response = self.hook.invoke_lambda(
  File "/usr/local/lib/python3.10/dist-packages/airflow/providers/amazon/aws/hooks/lambda_function.py", line 79, in invoke_lambda
    return self.conn.invoke(**trim_none_values(invoke_args))
  File "/home/fcmacedo/.local/lib/python3.10/site-packages/botocore/client.py", line 535, in _api_call
    return self._make_api_call(operation_name, kwargs)
  File "/home/fcmacedo/.local/lib/python3.10/site-packages/botocore/client.py", line 980, in _make_api_call
    raise error_class(parsed_response, operation_name)
botocore.exceptions.ClientError: An error occurred (InvalidSignatureException) when calling the Invoke operation: Signature expired: 20240126T173419Z is now earlier than 20240126T174843Z (20240126T175343Z - 5 min.)
[2024-01-26T14:34:20.480-0300] {taskinstance.py:1400} INFO - Marking task as FAILED. dag_id=how-desafio-03, task_id=invoke_lambda_function, execution_date=20240126T173415, start_date=20240126T173419, end_date=20240126T173420
[2024-01-26T14:34:20.509-0300] {standard_task_runner.py:104} ERROR - Failed to execute job 229 for task invoke_lambda_function (An error occurred (InvalidSignatureException) when calling the Invoke operation: Signature expired: 20240126T173419Z is now earlier than 20240126T174843Z (20240126T175343Z - 5 min.); 3771)
[2024-01-26T14:34:20.536-0300] {local_task_job_runner.py:228} INFO - Task exited with return code 1
[2024-01-26T14:34:20.574-0300] {taskinstance.py:2778} INFO - 0 downstream tasks scheduled from follow-on schedule check
