[2023-10-18T20:34:01.607-0300] {logging_mixin.py:151} INFO - Changing /mnt/c/Users/filipe.macedo_ifood/Documents/how-desafio-03/airflow/logs/dag_id=how-desafio-03/run_id=scheduled__2023-10-17T09:10:00+00:00/task_id=invoke_lambda_function permission to 509
[2023-10-18T20:34:01.662-0300] {logging_mixin.py:151} INFO - Changing /mnt/c/Users/filipe.macedo_ifood/Documents/how-desafio-03/airflow/logs/dag_id=how-desafio-03/run_id=scheduled__2023-10-17T09:10:00+00:00/task_id=invoke_lambda_function permission to 509
[2023-10-18T20:34:01.681-0300] {taskinstance.py:1159} INFO - Dependencies all met for dep_context=non-requeueable deps ti=<TaskInstance: how-desafio-03.invoke_lambda_function scheduled__2023-10-17T09:10:00+00:00 [queued]>
[2023-10-18T20:34:01.697-0300] {taskinstance.py:1159} INFO - Dependencies all met for dep_context=requeueable deps ti=<TaskInstance: how-desafio-03.invoke_lambda_function scheduled__2023-10-17T09:10:00+00:00 [queued]>
[2023-10-18T20:34:01.698-0300] {taskinstance.py:1361} INFO - Starting attempt 1 of 1
[2023-10-18T20:34:01.731-0300] {taskinstance.py:1382} INFO - Executing <Task(LambdaInvokeFunctionOperator): invoke_lambda_function> on 2023-10-17 09:10:00+00:00
[2023-10-18T20:34:01.732-0300] {standard_task_runner.py:57} INFO - Started process 126 to run task
[2023-10-18T20:34:01.735-0300] {standard_task_runner.py:84} INFO - Running: ['airflow', 'tasks', 'run', 'how-desafio-03', 'invoke_lambda_function', 'scheduled__2023-10-17T09:10:00+00:00', '--job-id', '15', '--raw', '--subdir', 'DAGS_FOLDER/weather_dag.py', '--cfg-path', '/tmp/tmpwxkjkynx']
[2023-10-18T20:34:01.736-0300] {standard_task_runner.py:85} INFO - Job 15: Subtask invoke_lambda_function
[2023-10-18T20:34:01.808-0300] {logging_mixin.py:151} INFO - Changing /mnt/c/Users/filipe.macedo_ifood/Documents/how-desafio-03/airflow/logs/dag_id=how-desafio-03/run_id=scheduled__2023-10-17T09:10:00+00:00/task_id=invoke_lambda_function permission to 509
[2023-10-18T20:34:01.810-0300] {task_command.py:416} INFO - Running <TaskInstance: how-desafio-03.invoke_lambda_function scheduled__2023-10-17T09:10:00+00:00 [running]> on host 14111-NB.
[2023-10-18T20:34:01.955-0300] {taskinstance.py:1662} INFO - Exporting env vars: AIRFLOW_CTX_DAG_OWNER='airflow' AIRFLOW_CTX_DAG_ID='how-desafio-03' AIRFLOW_CTX_TASK_ID='invoke_lambda_function' AIRFLOW_CTX_EXECUTION_DATE='2023-10-17T09:10:00+00:00' AIRFLOW_CTX_TRY_NUMBER='1' AIRFLOW_CTX_DAG_RUN_ID='scheduled__2023-10-17T09:10:00+00:00'
[2023-10-18T20:34:01.956-0300] {lambda_function.py:211} INFO - Invoking AWS Lambda function: my_first_test with payload: None
[2023-10-18T20:34:01.970-0300] {base.py:73} INFO - Using connection ID 'aws_default' for task execution.
[2023-10-18T20:34:01.971-0300] {connection_wrapper.py:340} INFO - AWS Connection (conn_id='aws_default', conn_type='aws') credentials retrieved from login and password.
[2023-10-18T20:34:02.134-0300] {taskinstance.py:1937} ERROR - Task failed with exception
Traceback (most recent call last):
  File "/usr/local/lib/python3.10/dist-packages/airflow/providers/amazon/aws/operators/lambda_function.py", line 212, in execute
    response = self.hook.invoke_lambda(
  File "/usr/local/lib/python3.10/dist-packages/airflow/providers/amazon/aws/hooks/lambda_function.py", line 79, in invoke_lambda
    return self.conn.invoke(**trim_none_values(invoke_args))
  File "/usr/lib/python3.10/functools.py", line 981, in __get__
    val = self.func(instance)
  File "/usr/local/lib/python3.10/dist-packages/airflow/providers/amazon/aws/hooks/base_aws.py", line 657, in conn
    return self.get_client_type(region_name=self.region_name)
  File "/usr/local/lib/python3.10/dist-packages/airflow/providers/amazon/aws/hooks/base_aws.py", line 622, in get_client_type
    return session.client(
  File "/usr/local/lib/python3.10/dist-packages/boto3/session.py", line 299, in client
    return self._session.create_client(
  File "/usr/local/lib/python3.10/dist-packages/botocore/session.py", line 997, in create_client
    client = client_creator.create_client(
  File "/usr/local/lib/python3.10/dist-packages/botocore/client.py", line 159, in create_client
    client_args = self._get_client_args(
  File "/usr/local/lib/python3.10/dist-packages/botocore/client.py", line 490, in _get_client_args
    return args_creator.get_client_args(
  File "/usr/local/lib/python3.10/dist-packages/botocore/args.py", line 100, in get_client_args
    final_args = self.compute_client_args(
  File "/usr/local/lib/python3.10/dist-packages/botocore/args.py", line 219, in compute_client_args
    endpoint_config = self._compute_endpoint_config(
  File "/usr/local/lib/python3.10/dist-packages/botocore/args.py", line 368, in _compute_endpoint_config
    return self._resolve_endpoint(**resolve_endpoint_kwargs)
  File "/usr/local/lib/python3.10/dist-packages/botocore/args.py", line 473, in _resolve_endpoint
    return endpoint_bridge.resolve(
  File "/usr/local/lib/python3.10/dist-packages/botocore/client.py", line 595, in resolve
    resolved = self.endpoint_resolver.construct_endpoint(
  File "/usr/local/lib/python3.10/dist-packages/botocore/regions.py", line 229, in construct_endpoint
    result = self._endpoint_for_partition(
  File "/usr/local/lib/python3.10/dist-packages/botocore/regions.py", line 277, in _endpoint_for_partition
    raise NoRegionError()
botocore.exceptions.NoRegionError: You must specify a region.
[2023-10-18T20:34:02.150-0300] {taskinstance.py:1400} INFO - Marking task as FAILED. dag_id=how-desafio-03, task_id=invoke_lambda_function, execution_date=20231017T091000, start_date=20231018T233401, end_date=20231018T233402
[2023-10-18T20:34:02.189-0300] {standard_task_runner.py:104} ERROR - Failed to execute job 15 for task invoke_lambda_function (You must specify a region.; 126)
[2023-10-18T20:34:02.229-0300] {local_task_job_runner.py:228} INFO - Task exited with return code 1
[2023-10-18T20:34:02.258-0300] {taskinstance.py:2778} INFO - 0 downstream tasks scheduled from follow-on schedule check
