[2024-01-27T13:03:34.848-0300] {logging_mixin.py:151} INFO - Changing /mnt/c/Users/filipe.macedo_ifood/Documents/how-desafio-03/airflow/logs/dag_id=how-desafio-3/run_id=scheduled__2024-01-27T15:45:00+00:00/task_id=invoke_lambda_function permission to 509
[2024-01-27T13:03:34.905-0300] {logging_mixin.py:151} INFO - Changing /mnt/c/Users/filipe.macedo_ifood/Documents/how-desafio-03/airflow/logs/dag_id=how-desafio-3/run_id=scheduled__2024-01-27T15:45:00+00:00/task_id=invoke_lambda_function permission to 509
[2024-01-27T13:03:34.929-0300] {taskinstance.py:1159} INFO - Dependencies all met for dep_context=non-requeueable deps ti=<TaskInstance: how-desafio-3.invoke_lambda_function scheduled__2024-01-27T15:45:00+00:00 [queued]>
[2024-01-27T13:03:34.942-0300] {taskinstance.py:1159} INFO - Dependencies all met for dep_context=requeueable deps ti=<TaskInstance: how-desafio-3.invoke_lambda_function scheduled__2024-01-27T15:45:00+00:00 [queued]>
[2024-01-27T13:03:34.943-0300] {taskinstance.py:1361} INFO - Starting attempt 1 of 1
[2024-01-27T13:03:34.973-0300] {taskinstance.py:1382} INFO - Executing <Task(LambdaInvokeFunctionOperator): invoke_lambda_function> on 2024-01-27 15:45:00+00:00
[2024-01-27T13:03:34.975-0300] {standard_task_runner.py:57} INFO - Started process 121 to run task
[2024-01-27T13:03:34.978-0300] {standard_task_runner.py:84} INFO - Running: ['airflow', 'tasks', 'run', 'how-desafio-3', 'invoke_lambda_function', 'scheduled__2024-01-27T15:45:00+00:00', '--job-id', '285', '--raw', '--subdir', 'DAGS_FOLDER/weather_dag.py', '--cfg-path', '/tmp/tmp9upb_ec1']
[2024-01-27T13:03:34.979-0300] {standard_task_runner.py:85} INFO - Job 285: Subtask invoke_lambda_function
[2024-01-27T13:03:35.051-0300] {logging_mixin.py:151} INFO - Changing /mnt/c/Users/filipe.macedo_ifood/Documents/how-desafio-03/airflow/logs/dag_id=how-desafio-3/run_id=scheduled__2024-01-27T15:45:00+00:00/task_id=invoke_lambda_function permission to 509
[2024-01-27T13:03:35.053-0300] {task_command.py:416} INFO - Running <TaskInstance: how-desafio-3.invoke_lambda_function scheduled__2024-01-27T15:45:00+00:00 [running]> on host 14111-NB.
[2024-01-27T13:03:35.144-0300] {taskinstance.py:1662} INFO - Exporting env vars: AIRFLOW_CTX_DAG_OWNER='airflow' AIRFLOW_CTX_DAG_ID='how-desafio-3' AIRFLOW_CTX_TASK_ID='invoke_lambda_function' AIRFLOW_CTX_EXECUTION_DATE='2024-01-27T15:45:00+00:00' AIRFLOW_CTX_TRY_NUMBER='1' AIRFLOW_CTX_DAG_RUN_ID='scheduled__2024-01-27T15:45:00+00:00'
[2024-01-27T13:03:35.144-0300] {lambda_function.py:211} INFO - Invoking AWS Lambda function: how-desafio-3 with payload: {"date": "1706371200"}
[2024-01-27T13:03:35.154-0300] {base.py:73} INFO - Using connection ID 'aws_default' for task execution.
[2024-01-27T13:03:35.155-0300] {connection_wrapper.py:340} INFO - AWS Connection (conn_id='aws_default', conn_type='aws') credentials retrieved from login and password.
[2024-01-27T13:03:36.281-0300] {taskinstance.py:1937} ERROR - Task failed with exception
Traceback (most recent call last):
  File "/usr/local/lib/python3.10/dist-packages/airflow/providers/amazon/aws/operators/lambda_function.py", line 212, in execute
    response = self.hook.invoke_lambda(
  File "/usr/local/lib/python3.10/dist-packages/airflow/providers/amazon/aws/hooks/lambda_function.py", line 79, in invoke_lambda
    return self.conn.invoke(**trim_none_values(invoke_args))
  File "/home/fcmacedo/.local/lib/python3.10/site-packages/botocore/client.py", line 535, in _api_call
    return self._make_api_call(operation_name, kwargs)
  File "/home/fcmacedo/.local/lib/python3.10/site-packages/botocore/client.py", line 980, in _make_api_call
    raise error_class(parsed_response, operation_name)
botocore.errorfactory.ResourceNotFoundException: An error occurred (ResourceNotFoundException) when calling the Invoke operation: Function not found: arn:aws:lambda:us-east-1:286277260287:function:how-desafio-3
[2024-01-27T13:03:36.307-0300] {taskinstance.py:1400} INFO - Marking task as FAILED. dag_id=how-desafio-3, task_id=invoke_lambda_function, execution_date=20240127T154500, start_date=20240127T160334, end_date=20240127T160336
[2024-01-27T13:03:36.339-0300] {standard_task_runner.py:104} ERROR - Failed to execute job 285 for task invoke_lambda_function (An error occurred (ResourceNotFoundException) when calling the Invoke operation: Function not found: arn:aws:lambda:us-east-1:286277260287:function:how-desafio-3; 121)
[2024-01-27T13:03:36.358-0300] {local_task_job_runner.py:228} INFO - Task exited with return code 1
[2024-01-27T13:03:36.379-0300] {taskinstance.py:2778} INFO - 0 downstream tasks scheduled from follow-on schedule check
