[2023-10-18T20:35:33.316-0300] {logging_mixin.py:151} INFO - Changing /mnt/c/Users/filipe.macedo_ifood/Documents/how-desafio-03/airflow/logs/dag_id=how-desafio-03/run_id=scheduled__2023-10-17T16:10:00+00:00/task_id=invoke_lambda_function permission to 509
[2023-10-18T20:35:33.372-0300] {logging_mixin.py:151} INFO - Changing /mnt/c/Users/filipe.macedo_ifood/Documents/how-desafio-03/airflow/logs/dag_id=how-desafio-03/run_id=scheduled__2023-10-17T16:10:00+00:00/task_id=invoke_lambda_function permission to 509
[2023-10-18T20:35:33.393-0300] {taskinstance.py:1159} INFO - Dependencies all met for dep_context=non-requeueable deps ti=<TaskInstance: how-desafio-03.invoke_lambda_function scheduled__2023-10-17T16:10:00+00:00 [queued]>
[2023-10-18T20:35:33.408-0300] {taskinstance.py:1159} INFO - Dependencies all met for dep_context=requeueable deps ti=<TaskInstance: how-desafio-03.invoke_lambda_function scheduled__2023-10-17T16:10:00+00:00 [queued]>
[2023-10-18T20:35:33.409-0300] {taskinstance.py:1361} INFO - Starting attempt 1 of 1
[2023-10-18T20:35:33.444-0300] {taskinstance.py:1382} INFO - Executing <Task(LambdaInvokeFunctionOperator): invoke_lambda_function> on 2023-10-17 16:10:00+00:00
[2023-10-18T20:35:33.447-0300] {standard_task_runner.py:57} INFO - Started process 145 to run task
[2023-10-18T20:35:33.449-0300] {standard_task_runner.py:84} INFO - Running: ['airflow', 'tasks', 'run', 'how-desafio-03', 'invoke_lambda_function', 'scheduled__2023-10-17T16:10:00+00:00', '--job-id', '23', '--raw', '--subdir', 'DAGS_FOLDER/weather_dag.py', '--cfg-path', '/tmp/tmptoj4pw2k']
[2023-10-18T20:35:33.450-0300] {standard_task_runner.py:85} INFO - Job 23: Subtask invoke_lambda_function
[2023-10-18T20:35:33.522-0300] {logging_mixin.py:151} INFO - Changing /mnt/c/Users/filipe.macedo_ifood/Documents/how-desafio-03/airflow/logs/dag_id=how-desafio-03/run_id=scheduled__2023-10-17T16:10:00+00:00/task_id=invoke_lambda_function permission to 509
[2023-10-18T20:35:33.525-0300] {task_command.py:416} INFO - Running <TaskInstance: how-desafio-03.invoke_lambda_function scheduled__2023-10-17T16:10:00+00:00 [running]> on host 14111-NB.
[2023-10-18T20:35:33.643-0300] {taskinstance.py:1662} INFO - Exporting env vars: AIRFLOW_CTX_DAG_OWNER='airflow' AIRFLOW_CTX_DAG_ID='how-desafio-03' AIRFLOW_CTX_TASK_ID='invoke_lambda_function' AIRFLOW_CTX_EXECUTION_DATE='2023-10-17T16:10:00+00:00' AIRFLOW_CTX_TRY_NUMBER='1' AIRFLOW_CTX_DAG_RUN_ID='scheduled__2023-10-17T16:10:00+00:00'
[2023-10-18T20:35:33.643-0300] {lambda_function.py:211} INFO - Invoking AWS Lambda function: my_first_test with payload: None
[2023-10-18T20:35:33.660-0300] {base.py:73} INFO - Using connection ID 'aws_default' for task execution.
[2023-10-18T20:35:33.661-0300] {connection_wrapper.py:340} INFO - AWS Connection (conn_id='aws_default', conn_type='aws') credentials retrieved from login and password.
[2023-10-18T20:35:34.888-0300] {taskinstance.py:1937} ERROR - Task failed with exception
Traceback (most recent call last):
  File "/usr/local/lib/python3.10/dist-packages/airflow/providers/amazon/aws/operators/lambda_function.py", line 212, in execute
    response = self.hook.invoke_lambda(
  File "/usr/local/lib/python3.10/dist-packages/airflow/providers/amazon/aws/hooks/lambda_function.py", line 79, in invoke_lambda
    return self.conn.invoke(**trim_none_values(invoke_args))
  File "/usr/local/lib/python3.10/dist-packages/botocore/client.py", line 535, in _api_call
    return self._make_api_call(operation_name, kwargs)
  File "/usr/local/lib/python3.10/dist-packages/botocore/client.py", line 980, in _make_api_call
    raise error_class(parsed_response, operation_name)
botocore.errorfactory.ResourceNotFoundException: An error occurred (ResourceNotFoundException) when calling the Invoke operation: Function not found: arn:aws:lambda:us-west-2:286277260287:function:my_first_test
[2023-10-18T20:35:34.901-0300] {taskinstance.py:1400} INFO - Marking task as FAILED. dag_id=how-desafio-03, task_id=invoke_lambda_function, execution_date=20231017T161000, start_date=20231018T233533, end_date=20231018T233534
[2023-10-18T20:35:34.939-0300] {standard_task_runner.py:104} ERROR - Failed to execute job 23 for task invoke_lambda_function (An error occurred (ResourceNotFoundException) when calling the Invoke operation: Function not found: arn:aws:lambda:us-west-2:286277260287:function:my_first_test; 145)
[2023-10-18T20:35:34.951-0300] {local_task_job_runner.py:228} INFO - Task exited with return code 1
[2023-10-18T20:35:34.974-0300] {taskinstance.py:2778} INFO - 0 downstream tasks scheduled from follow-on schedule check
