[2023-10-18T20:39:30.821-0300] {logging_mixin.py:151} INFO - Changing /mnt/c/Users/filipe.macedo_ifood/Documents/how-desafio-03/airflow/logs/dag_id=how-desafio-03/run_id=scheduled__2023-10-18T00:10:00+00:00/task_id=invoke_lambda_function permission to 509
[2023-10-18T20:39:30.886-0300] {logging_mixin.py:151} INFO - Changing /mnt/c/Users/filipe.macedo_ifood/Documents/how-desafio-03/airflow/logs/dag_id=how-desafio-03/run_id=scheduled__2023-10-18T00:10:00+00:00/task_id=invoke_lambda_function permission to 509
[2023-10-18T20:39:30.910-0300] {taskinstance.py:1159} INFO - Dependencies all met for dep_context=non-requeueable deps ti=<TaskInstance: how-desafio-03.invoke_lambda_function scheduled__2023-10-18T00:10:00+00:00 [queued]>
[2023-10-18T20:39:30.927-0300] {taskinstance.py:1159} INFO - Dependencies all met for dep_context=requeueable deps ti=<TaskInstance: how-desafio-03.invoke_lambda_function scheduled__2023-10-18T00:10:00+00:00 [queued]>
[2023-10-18T20:39:30.927-0300] {taskinstance.py:1361} INFO - Starting attempt 1 of 1
[2023-10-18T20:39:30.964-0300] {taskinstance.py:1382} INFO - Executing <Task(LambdaInvokeFunctionOperator): invoke_lambda_function> on 2023-10-18 00:10:00+00:00
[2023-10-18T20:39:30.966-0300] {standard_task_runner.py:57} INFO - Started process 171 to run task
[2023-10-18T20:39:30.967-0300] {standard_task_runner.py:84} INFO - Running: ['airflow', 'tasks', 'run', 'how-desafio-03', 'invoke_lambda_function', 'scheduled__2023-10-18T00:10:00+00:00', '--job-id', '32', '--raw', '--subdir', 'DAGS_FOLDER/weather_dag.py', '--cfg-path', '/tmp/tmp8dxw2qyd']
[2023-10-18T20:39:30.969-0300] {standard_task_runner.py:85} INFO - Job 32: Subtask invoke_lambda_function
[2023-10-18T20:39:31.039-0300] {logging_mixin.py:151} INFO - Changing /mnt/c/Users/filipe.macedo_ifood/Documents/how-desafio-03/airflow/logs/dag_id=how-desafio-03/run_id=scheduled__2023-10-18T00:10:00+00:00/task_id=invoke_lambda_function permission to 509
[2023-10-18T20:39:31.041-0300] {task_command.py:416} INFO - Running <TaskInstance: how-desafio-03.invoke_lambda_function scheduled__2023-10-18T00:10:00+00:00 [running]> on host 14111-NB.
[2023-10-18T20:39:31.150-0300] {taskinstance.py:1662} INFO - Exporting env vars: AIRFLOW_CTX_DAG_OWNER='airflow' AIRFLOW_CTX_DAG_ID='how-desafio-03' AIRFLOW_CTX_TASK_ID='invoke_lambda_function' AIRFLOW_CTX_EXECUTION_DATE='2023-10-18T00:10:00+00:00' AIRFLOW_CTX_TRY_NUMBER='1' AIRFLOW_CTX_DAG_RUN_ID='scheduled__2023-10-18T00:10:00+00:00'
[2023-10-18T20:39:31.150-0300] {lambda_function.py:211} INFO - Invoking AWS Lambda function: my_first_test with payload: None
[2023-10-18T20:39:31.163-0300] {base.py:73} INFO - Using connection ID 'aws_default' for task execution.
[2023-10-18T20:39:31.163-0300] {connection_wrapper.py:340} INFO - AWS Connection (conn_id='aws_default', conn_type='aws') credentials retrieved from login and password.
[2023-10-18T20:39:32.014-0300] {lambda_function.py:220} INFO - Lambda response metadata: {'RequestId': '52e01810-0163-4f4b-942f-20ab2d7ba097', 'HTTPStatusCode': 200, 'HTTPHeaders': {'date': 'Wed, 18 Oct 2023 23:39:33 GMT', 'content-type': 'application/json', 'content-length': '234', 'connection': 'keep-alive', 'x-amzn-requestid': '52e01810-0163-4f4b-942f-20ab2d7ba097', 'x-amz-function-error': 'Unhandled', 'x-amzn-remapped-content-length': '0', 'x-amz-executed-version': '$LATEST', 'x-amzn-trace-id': 'root=1-65306cb5-3b1a9ea3499c01d366ce4299;sampled=0;lineage=2d7f70ec:0'}, 'RetryAttempts': 0}
[2023-10-18T20:39:32.015-0300] {taskinstance.py:1937} ERROR - Task failed with exception
Traceback (most recent call last):
  File "/usr/local/lib/python3.10/dist-packages/airflow/providers/amazon/aws/operators/lambda_function.py", line 226, in execute
    raise ValueError(
ValueError: ('Lambda function execution resulted in error', {'ResponseMetadata': {'RequestId': '52e01810-0163-4f4b-942f-20ab2d7ba097', 'HTTPStatusCode': 200, 'HTTPHeaders': {'date': 'Wed, 18 Oct 2023 23:39:33 GMT', 'content-type': 'application/json', 'content-length': '234', 'connection': 'keep-alive', 'x-amzn-requestid': '52e01810-0163-4f4b-942f-20ab2d7ba097', 'x-amz-function-error': 'Unhandled', 'x-amzn-remapped-content-length': '0', 'x-amz-executed-version': '$LATEST', 'x-amzn-trace-id': 'root=1-65306cb5-3b1a9ea3499c01d366ce4299;sampled=0;lineage=2d7f70ec:0'}, 'RetryAttempts': 0}, 'Payload': '{"errorMessage": "\'key1\'", "errorType": "KeyError", "requestId": "52e01810-0163-4f4b-942f-20ab2d7ba097", "stackTrace": ["  File \\"/var/task/lambda_function.py\\", line 8, in lambda_handler\\n    print(\\"value1 = \\" + event[\'key1\'])\\n"]}'})
[2023-10-18T20:39:32.033-0300] {taskinstance.py:1400} INFO - Marking task as FAILED. dag_id=how-desafio-03, task_id=invoke_lambda_function, execution_date=20231018T001000, start_date=20231018T233930, end_date=20231018T233932
[2023-10-18T20:39:32.075-0300] {standard_task_runner.py:104} ERROR - Failed to execute job 32 for task invoke_lambda_function (('Lambda function execution resulted in error', {'ResponseMetadata': {'RequestId': '52e01810-0163-4f4b-942f-20ab2d7ba097', 'HTTPStatusCode': 200, 'HTTPHeaders': {'date': 'Wed, 18 Oct 2023 23:39:33 GMT', 'content-type': 'application/json', 'content-length': '234', 'connection': 'keep-alive', 'x-amzn-requestid': '52e01810-0163-4f4b-942f-20ab2d7ba097', 'x-amz-function-error': 'Unhandled', 'x-amzn-remapped-content-length': '0', 'x-amz-executed-version': '$LATEST', 'x-amzn-trace-id': 'root=1-65306cb5-3b1a9ea3499c01d366ce4299;sampled=0;lineage=2d7f70ec:0'}, 'RetryAttempts': 0}, 'Payload': '{"errorMessage": "\'key1\'", "errorType": "KeyError", "requestId": "52e01810-0163-4f4b-942f-20ab2d7ba097", "stackTrace": ["  File \\"/var/task/lambda_function.py\\", line 8, in lambda_handler\\n    print(\\"value1 = \\" + event[\'key1\'])\\n"]}'}); 171)
[2023-10-18T20:39:32.106-0300] {local_task_job_runner.py:228} INFO - Task exited with return code 1
[2023-10-18T20:39:32.143-0300] {taskinstance.py:2778} INFO - 0 downstream tasks scheduled from follow-on schedule check
